<?xml version="1.0"?>
<robot name="the_simplest_diffbot" xmlns:xacro="http://ros.org/wiki/xacro"> 
  
  <xacro:include filename="$(find basic_diffbot)/urdf/the_simplest_diffbot_gz.xacro"/>
  
  
  <link name="base_footprint"/>

  <joint name="base_joint" type="fixed">
    <parent link="base_footprint"/>
    <child link="base_link"/>
    <origin xyz="0 0 0.01" rpy="0 0 0"/>
  </joint>

  <link name="base_link"> <!-- Important: Every visual, collision and inertial tag has its own origin -->
    <visual>
      <origin xyz="-0.033 0.0 0.04" rpy="0 0 0"/>
      <geometry>
        <box size="0.2 0.1 0.06"/>
      </geometry>
    </visual>
    <collision>
      <origin xyz="-0.033 0 0.04" rpy="0 0 0"/>
      <geometry>
        <box size="0.2 0.1 0.06"/>
      </geometry>
    </collision>
    <inertial>
      <origin xyz="0 0 0.06" rpy="0 0 0"/>
      <mass value="10"/>
      <inertia ixx="0.333333" ixy="0.0" ixz="0.0"  iyy="0.333333" iyz="0.0"  izz="0.6" />
    </inertial>
  </link>


  <!-- Wheels definition (joints and links) -->
  <joint name="wheel_left_joint" type="continuous">
    <parent link="base_link"/>
    <child link="wheel_left_link"/>
    <origin xyz="0 0.065 0.025" rpy="-1.57 0 0"/> <!-- in rad -->
    <axis xyz="0 0 1"/>
  </joint>

  <link name="wheel_left_link">
    <visual>
      <origin xyz="0 0 0.015" rpy="0 0 0"/>
      <geometry>
        <cylinder length="0.024" radius="0.035"/>
      </geometry>
    </visual>
    <collision>
      <origin xyz="0 0 0" rpy="0 0 0"/>
      <geometry>
        <cylinder length="0.024" radius="0.035"/>
      </geometry>
    </collision>
    <inertial>
      <origin xyz="0 0 0" />
      <mass value="5" />
      <inertia ixx="0.0135417" ixy="0.0" ixz="0.0"  iyy="0.0135417" iyz="0.0"  izz="0.025" />
      </inertial>
  </link>

  <joint name="wheel_right_joint" type="continuous">
    <parent link="base_link"/>
    <child link="wheel_right_link"/>
    <origin xyz="0 -0.065 0.025" rpy="-1.57 0 0"/>
    <axis xyz="0 0 1"/>
  </joint>

  <link name="wheel_right_link">
    <visual>
      <origin xyz="0 0 -0.015" rpy="0 0 0"/>
      <geometry>
        <cylinder length="0.024" radius="0.035"/>
      </geometry>
    </visual>
    <collision>
      <origin xyz="0 0 0" rpy="0 0 0"/>
      <geometry>
        <cylinder length="0.024" radius="0.035"/>
      </geometry>
    </collision>
    <inertial>
      <origin xyz="0 0 0" />
      <mass value="5" />
      <inertia ixx="0.0135417" ixy="0.0" ixz="0.0"  iyy="0.0135417" iyz="0.0"  izz="0.025" />
    </inertial>
  </link>

  <!-- Caster wheel definition (joint and link) -->
  <joint name="caster_base_joint" type="fixed">
    <origin xyz="-0.1 0 0.001" rpy="0 0 0" /> <!-- a small vertical offset is required -->
    <parent link="base_link" />
    <child link="caster_base_link" />
  </joint>
  
  <link name="caster_base_link">
    <visual>
      <origin xyz="0 0 0" rpy="0 0 0" />
      <geometry>
        <sphere radius="0.01"/>
      </geometry>
    </visual>
    <collision>
      <origin xyz="0 0 0" rpy="0 0 0"/>
      <geometry>
        <sphere radius="0.01"/>
      </geometry>
    </collision>
    <collision>
      <origin xyz="0.17 0 0" rpy="0 0 0"/>
      <geometry>
        <sphere radius="0.01"/>
      </geometry>
    </collision>
    <!-- Inertial tag is optional for this case -->
  </link>

</robot>

